warning: initial DIIS convergence failed, trying quadradic convergence
Process Process-1:
Traceback (most recent call last):
  File "/n/home03/cwagen/.conda/envs/openmm/lib/python3.7/multiprocessing/process.py", line 297, in _bootstrap
    self.run()
  File "/n/home03/cwagen/.conda/envs/openmm/lib/python3.7/multiprocessing/process.py", line 99, in run
    self._target(*self._args, **self._kwargs)
  File "/n/home03/cwagen/.conda/envs/openmm/lib/python3.7/site-packages/presto/calculators.py", line 378, in evaluate
    energy += e
TypeError: unsupported operand type(s) for +: 'NoneType' and 'float'
warning: initial DIIS convergence failed, trying quadradic convergence
Process Process-7:
Traceback (most recent call last):
  File "/n/home03/cwagen/.conda/envs/openmm/lib/python3.7/multiprocessing/process.py", line 297, in _bootstrap
    self.run()
  File "/n/home03/cwagen/.conda/envs/openmm/lib/python3.7/multiprocessing/process.py", line 99, in run
    self._target(*self._args, **self._kwargs)
  File "/n/home03/cwagen/.conda/envs/openmm/lib/python3.7/site-packages/presto/calculators.py", line 378, in evaluate
    energy += e
TypeError: unsupported operand type(s) for +: 'NoneType' and 'float'
warning: initial DIIS convergence failed, trying quadradic convergence
Process Process-10:
Traceback (most recent call last):
  File "/n/home03/cwagen/.conda/envs/openmm/lib/python3.7/multiprocessing/process.py", line 297, in _bootstrap
    self.run()
  File "/n/home03/cwagen/.conda/envs/openmm/lib/python3.7/multiprocessing/process.py", line 99, in run
    self._target(*self._args, **self._kwargs)
  File "/n/home03/cwagen/.conda/envs/openmm/lib/python3.7/site-packages/presto/calculators.py", line 378, in evaluate
    energy += e
TypeError: unsupported operand type(s) for +: 'NoneType' and 'float'
warning: initial DIIS convergence failed, trying quadradic convergence
Process Process-13:
Traceback (most recent call last):
  File "/n/home03/cwagen/.conda/envs/openmm/lib/python3.7/multiprocessing/process.py", line 297, in _bootstrap
    self.run()
  File "/n/home03/cwagen/.conda/envs/openmm/lib/python3.7/multiprocessing/process.py", line 99, in run
    self._target(*self._args, **self._kwargs)
  File "/n/home03/cwagen/.conda/envs/openmm/lib/python3.7/site-packages/presto/calculators.py", line 378, in evaluate
    energy += e
TypeError: unsupported operand type(s) for +: 'NoneType' and 'float'
warning: initial DIIS convergence failed, trying quadradic convergence
Process Process-19:
Traceback (most recent call last):
  File "/n/home03/cwagen/.conda/envs/openmm/lib/python3.7/multiprocessing/process.py", line 297, in _bootstrap
    self.run()
  File "/n/home03/cwagen/.conda/envs/openmm/lib/python3.7/multiprocessing/process.py", line 99, in run
    self._target(*self._args, **self._kwargs)
  File "/n/home03/cwagen/.conda/envs/openmm/lib/python3.7/site-packages/presto/calculators.py", line 378, in evaluate
    energy += e
TypeError: unsupported operand type(s) for +: 'NoneType' and 'float'
warning: initial DIIS convergence failed, trying quadradic convergence
Process Process-22:
Traceback (most recent call last):
  File "/n/home03/cwagen/.conda/envs/openmm/lib/python3.7/multiprocessing/process.py", line 297, in _bootstrap
    self.run()
  File "/n/home03/cwagen/.conda/envs/openmm/lib/python3.7/multiprocessing/process.py", line 99, in run
    self._target(*self._args, **self._kwargs)
  File "/n/home03/cwagen/.conda/envs/openmm/lib/python3.7/site-packages/presto/calculators.py", line 378, in evaluate
    energy += e
TypeError: unsupported operand type(s) for +: 'NoneType' and 'float'
warning: initial DIIS convergence failed, trying quadradic convergence
Process Process-25:
Traceback (most recent call last):
  File "/n/home03/cwagen/.conda/envs/openmm/lib/python3.7/multiprocessing/process.py", line 297, in _bootstrap
    self.run()
  File "/n/home03/cwagen/.conda/envs/openmm/lib/python3.7/multiprocessing/process.py", line 99, in run
    self._target(*self._args, **self._kwargs)
  File "/n/home03/cwagen/.conda/envs/openmm/lib/python3.7/site-packages/presto/calculators.py", line 378, in evaluate
    energy += e
TypeError: unsupported operand type(s) for +: 'NoneType' and 'float'
warning: initial DIIS convergence failed, trying quadradic convergence
Process Process-28:
Traceback (most recent call last):
  File "/n/home03/cwagen/.conda/envs/openmm/lib/python3.7/multiprocessing/process.py", line 297, in _bootstrap
    self.run()
  File "/n/home03/cwagen/.conda/envs/openmm/lib/python3.7/multiprocessing/process.py", line 99, in run
    self._target(*self._args, **self._kwargs)
  File "/n/home03/cwagen/.conda/envs/openmm/lib/python3.7/site-packages/presto/calculators.py", line 378, in evaluate
    energy += e
TypeError: unsupported operand type(s) for +: 'NoneType' and 'float'
warning: initial DIIS convergence failed, trying quadradic convergence
Process Process-31:
Traceback (most recent call last):
  File "/n/home03/cwagen/.conda/envs/openmm/lib/python3.7/multiprocessing/process.py", line 297, in _bootstrap
    self.run()
  File "/n/home03/cwagen/.conda/envs/openmm/lib/python3.7/multiprocessing/process.py", line 99, in run
    self._target(*self._args, **self._kwargs)
  File "/n/home03/cwagen/.conda/envs/openmm/lib/python3.7/site-packages/presto/calculators.py", line 378, in evaluate
    energy += e
TypeError: unsupported operand type(s) for +: 'NoneType' and 'float'
warning: initial DIIS convergence failed, trying quadradic convergence
Process Process-34:
Traceback (most recent call last):
  File "/n/home03/cwagen/.conda/envs/openmm/lib/python3.7/multiprocessing/process.py", line 297, in _bootstrap
    self.run()
  File "/n/home03/cwagen/.conda/envs/openmm/lib/python3.7/multiprocessing/process.py", line 99, in run
    self._target(*self._args, **self._kwargs)
  File "/n/home03/cwagen/.conda/envs/openmm/lib/python3.7/site-packages/presto/calculators.py", line 378, in evaluate
    energy += e
TypeError: unsupported operand type(s) for +: 'NoneType' and 'float'
warning: initial DIIS convergence failed, trying quadradic convergence
Process Process-37:
Traceback (most recent call last):
  File "/n/home03/cwagen/.conda/envs/openmm/lib/python3.7/multiprocessing/process.py", line 297, in _bootstrap
    self.run()
  File "/n/home03/cwagen/.conda/envs/openmm/lib/python3.7/multiprocessing/process.py", line 99, in run
    self._target(*self._args, **self._kwargs)
  File "/n/home03/cwagen/.conda/envs/openmm/lib/python3.7/site-packages/presto/calculators.py", line 378, in evaluate
    energy += e
TypeError: unsupported operand type(s) for +: 'NoneType' and 'float'
warning: initial DIIS convergence failed, trying quadradic convergence
Process Process-40:
Traceback (most recent call last):
  File "/n/home03/cwagen/.conda/envs/openmm/lib/python3.7/multiprocessing/process.py", line 297, in _bootstrap
    self.run()
  File "/n/home03/cwagen/.conda/envs/openmm/lib/python3.7/multiprocessing/process.py", line 99, in run
    self._target(*self._args, **self._kwargs)
  File "/n/home03/cwagen/.conda/envs/openmm/lib/python3.7/site-packages/presto/calculators.py", line 378, in evaluate
    energy += e
TypeError: unsupported operand type(s) for +: 'NoneType' and 'float'
warning: initial DIIS convergence failed, trying quadradic convergence
Process Process-43:
Traceback (most recent call last):
  File "/n/home03/cwagen/.conda/envs/openmm/lib/python3.7/multiprocessing/process.py", line 297, in _bootstrap
    self.run()
  File "/n/home03/cwagen/.conda/envs/openmm/lib/python3.7/multiprocessing/process.py", line 99, in run
    self._target(*self._args, **self._kwargs)
  File "/n/home03/cwagen/.conda/envs/openmm/lib/python3.7/site-packages/presto/calculators.py", line 378, in evaluate
    energy += e
TypeError: unsupported operand type(s) for +: 'NoneType' and 'float'
warning: initial DIIS convergence failed, trying quadradic convergence
Process Process-46:
Traceback (most recent call last):
  File "/n/home03/cwagen/.conda/envs/openmm/lib/python3.7/multiprocessing/process.py", line 297, in _bootstrap
    self.run()
  File "/n/home03/cwagen/.conda/envs/openmm/lib/python3.7/multiprocessing/process.py", line 99, in run
    self._target(*self._args, **self._kwargs)
  File "/n/home03/cwagen/.conda/envs/openmm/lib/python3.7/site-packages/presto/calculators.py", line 378, in evaluate
    energy += e
TypeError: unsupported operand type(s) for +: 'NoneType' and 'float'
warning: initial DIIS convergence failed, trying quadradic convergence
Process Process-49:
Traceback (most recent call last):
  File "/n/home03/cwagen/.conda/envs/openmm/lib/python3.7/multiprocessing/process.py", line 297, in _bootstrap
    self.run()
  File "/n/home03/cwagen/.conda/envs/openmm/lib/python3.7/multiprocessing/process.py", line 99, in run
    self._target(*self._args, **self._kwargs)
  File "/n/home03/cwagen/.conda/envs/openmm/lib/python3.7/site-packages/presto/calculators.py", line 378, in evaluate
    energy += e
TypeError: unsupported operand type(s) for +: 'NoneType' and 'float'
warning: initial DIIS convergence failed, trying quadradic convergence
Process Process-52:
Traceback (most recent call last):
  File "/n/home03/cwagen/.conda/envs/openmm/lib/python3.7/multiprocessing/process.py", line 297, in _bootstrap
    self.run()
  File "/n/home03/cwagen/.conda/envs/openmm/lib/python3.7/multiprocessing/process.py", line 99, in run
    self._target(*self._args, **self._kwargs)
  File "/n/home03/cwagen/.conda/envs/openmm/lib/python3.7/site-packages/presto/calculators.py", line 378, in evaluate
    energy += e
TypeError: unsupported operand type(s) for +: 'NoneType' and 'float'
warning: initial DIIS convergence failed, trying quadradic convergence
Process Process-55:
Traceback (most recent call last):
  File "/n/home03/cwagen/.conda/envs/openmm/lib/python3.7/multiprocessing/process.py", line 297, in _bootstrap
    self.run()
  File "/n/home03/cwagen/.conda/envs/openmm/lib/python3.7/multiprocessing/process.py", line 99, in run
    self._target(*self._args, **self._kwargs)
  File "/n/home03/cwagen/.conda/envs/openmm/lib/python3.7/site-packages/presto/calculators.py", line 378, in evaluate
    energy += e
TypeError: unsupported operand type(s) for +: 'NoneType' and 'float'
warning: initial DIIS convergence failed, trying quadradic convergence
Process Process-58:
Traceback (most recent call last):
  File "/n/home03/cwagen/.conda/envs/openmm/lib/python3.7/multiprocessing/process.py", line 297, in _bootstrap
    self.run()
  File "/n/home03/cwagen/.conda/envs/openmm/lib/python3.7/multiprocessing/process.py", line 99, in run
    self._target(*self._args, **self._kwargs)
  File "/n/home03/cwagen/.conda/envs/openmm/lib/python3.7/site-packages/presto/calculators.py", line 378, in evaluate
    energy += e
TypeError: unsupported operand type(s) for +: 'NoneType' and 'float'
warning: initial DIIS convergence failed, trying quadradic convergence
Process Process-61:
Traceback (most recent call last):
  File "/n/home03/cwagen/.conda/envs/openmm/lib/python3.7/multiprocessing/process.py", line 297, in _bootstrap
    self.run()
  File "/n/home03/cwagen/.conda/envs/openmm/lib/python3.7/multiprocessing/process.py", line 99, in run
    self._target(*self._args, **self._kwargs)
  File "/n/home03/cwagen/.conda/envs/openmm/lib/python3.7/site-packages/presto/calculators.py", line 378, in evaluate
    energy += e
TypeError: unsupported operand type(s) for +: 'NoneType' and 'float'
warning: initial DIIS convergence failed, trying quadradic convergence
Process Process-64:
Traceback (most recent call last):
  File "/n/home03/cwagen/.conda/envs/openmm/lib/python3.7/multiprocessing/process.py", line 297, in _bootstrap
    self.run()
  File "/n/home03/cwagen/.conda/envs/openmm/lib/python3.7/multiprocessing/process.py", line 99, in run
    self._target(*self._args, **self._kwargs)
  File "/n/home03/cwagen/.conda/envs/openmm/lib/python3.7/site-packages/presto/calculators.py", line 378, in evaluate
    energy += e
TypeError: unsupported operand type(s) for +: 'NoneType' and 'float'
warning: initial DIIS convergence failed, trying quadradic convergence
Process Process-67:
Traceback (most recent call last):
  File "/n/home03/cwagen/.conda/envs/openmm/lib/python3.7/multiprocessing/process.py", line 297, in _bootstrap
    self.run()
  File "/n/home03/cwagen/.conda/envs/openmm/lib/python3.7/multiprocessing/process.py", line 99, in run
    self._target(*self._args, **self._kwargs)
  File "/n/home03/cwagen/.conda/envs/openmm/lib/python3.7/site-packages/presto/calculators.py", line 378, in evaluate
    energy += e
TypeError: unsupported operand type(s) for +: 'NoneType' and 'float'
warning: initial DIIS convergence failed, trying quadradic convergence
Process Process-70:
Traceback (most recent call last):
  File "/n/home03/cwagen/.conda/envs/openmm/lib/python3.7/multiprocessing/process.py", line 297, in _bootstrap
    self.run()
  File "/n/home03/cwagen/.conda/envs/openmm/lib/python3.7/multiprocessing/process.py", line 99, in run
    self._target(*self._args, **self._kwargs)
  File "/n/home03/cwagen/.conda/envs/openmm/lib/python3.7/site-packages/presto/calculators.py", line 378, in evaluate
    energy += e
TypeError: unsupported operand type(s) for +: 'NoneType' and 'float'
warning: initial DIIS convergence failed, trying quadradic convergence
Process Process-73:
Traceback (most recent call last):
  File "/n/home03/cwagen/.conda/envs/openmm/lib/python3.7/multiprocessing/process.py", line 297, in _bootstrap
    self.run()
  File "/n/home03/cwagen/.conda/envs/openmm/lib/python3.7/multiprocessing/process.py", line 99, in run
    self._target(*self._args, **self._kwargs)
  File "/n/home03/cwagen/.conda/envs/openmm/lib/python3.7/site-packages/presto/calculators.py", line 378, in evaluate
    energy += e
TypeError: unsupported operand type(s) for +: 'NoneType' and 'float'
warning: initial DIIS convergence failed, trying quadradic convergence
Process Process-76:
Traceback (most recent call last):
  File "/n/home03/cwagen/.conda/envs/openmm/lib/python3.7/multiprocessing/process.py", line 297, in _bootstrap
    self.run()
  File "/n/home03/cwagen/.conda/envs/openmm/lib/python3.7/multiprocessing/process.py", line 99, in run
    self._target(*self._args, **self._kwargs)
  File "/n/home03/cwagen/.conda/envs/openmm/lib/python3.7/site-packages/presto/calculators.py", line 378, in evaluate
    energy += e
TypeError: unsupported operand type(s) for +: 'NoneType' and 'float'
warning: initial DIIS convergence failed, trying quadradic convergence
Process Process-79:
Traceback (most recent call last):
  File "/n/home03/cwagen/.conda/envs/openmm/lib/python3.7/multiprocessing/process.py", line 297, in _bootstrap
    self.run()
  File "/n/home03/cwagen/.conda/envs/openmm/lib/python3.7/multiprocessing/process.py", line 99, in run
    self._target(*self._args, **self._kwargs)
  File "/n/home03/cwagen/.conda/envs/openmm/lib/python3.7/site-packages/presto/calculators.py", line 378, in evaluate
    energy += e
TypeError: unsupported operand type(s) for +: 'NoneType' and 'float'
warning: initial DIIS convergence failed, trying quadradic convergence
Process Process-82:
Traceback (most recent call last):
  File "/n/home03/cwagen/.conda/envs/openmm/lib/python3.7/multiprocessing/process.py", line 297, in _bootstrap
    self.run()
  File "/n/home03/cwagen/.conda/envs/openmm/lib/python3.7/multiprocessing/process.py", line 99, in run
    self._target(*self._args, **self._kwargs)
  File "/n/home03/cwagen/.conda/envs/openmm/lib/python3.7/site-packages/presto/calculators.py", line 378, in evaluate
    energy += e
TypeError: unsupported operand type(s) for +: 'NoneType' and 'float'
warning: initial DIIS convergence failed, trying quadradic convergence
Process Process-88:
Traceback (most recent call last):
  File "/n/home03/cwagen/.conda/envs/openmm/lib/python3.7/site-packages/presto/calculators.py", line 347, in evaluate
    gaussian_file = cctk.GaussianFile.read_file(output_filename)
  File "/n/home03/cwagen/.conda/envs/openmm/lib/python3.7/site-packages/cctk/gaussian_file.py", line 719, in read_file
    files.append(parse.read_file_fast(lines, filename, link1idx, extended_opt_info=extended_opt_info))
  File "/n/home03/cwagen/.conda/envs/openmm/lib/python3.7/site-packages/cctk/parse_gaussian.py", line 331, in read_file_fast
    forces = parse_forces(block_matches[7])
  File "/n/home03/cwagen/.conda/envs/openmm/lib/python3.7/site-packages/cctk/parse_gaussian.py", line 465, in parse_forces
    for line in force_block[0].split("\n")[2:]:
IndexError: list index out of range

During handling of the above exception, another exception occurred:

Traceback (most recent call last):
  File "/n/home03/cwagen/.conda/envs/openmm/lib/python3.7/site-packages/presto/calculators.py", line 347, in evaluate
    gaussian_file = cctk.GaussianFile.read_file(output_filename)
  File "/n/home03/cwagen/.conda/envs/openmm/lib/python3.7/site-packages/cctk/gaussian_file.py", line 719, in read_file
    files.append(parse.read_file_fast(lines, filename, link1idx, extended_opt_info=extended_opt_info))
  File "/n/home03/cwagen/.conda/envs/openmm/lib/python3.7/site-packages/cctk/parse_gaussian.py", line 331, in read_file_fast
    forces = parse_forces(block_matches[7])
  File "/n/home03/cwagen/.conda/envs/openmm/lib/python3.7/site-packages/cctk/parse_gaussian.py", line 465, in parse_forces
    for line in force_block[0].split("\n")[2:]:
IndexError: list index out of range

During handling of the above exception, another exception occurred:

Traceback (most recent call last):
  File "/n/home03/cwagen/.conda/envs/openmm/lib/python3.7/site-packages/presto/calculators.py", line 357, in evaluate
    assert qc is False
AssertionError

During handling of the above exception, another exception occurred:

Traceback (most recent call last):
  File "/n/home03/cwagen/.conda/envs/openmm/lib/python3.7/site-packages/presto/calculators.py", line 358, in evaluate
    self.evaluate(atomic_numbers, positions, high_atoms, pipe, print_timing, qc=True)
  File "/n/home03/cwagen/.conda/envs/openmm/lib/python3.7/site-packages/presto/calculators.py", line 362, in evaluate
    raise ValueError(f"can't parse Gaussian output file - copied to {old_working_directory}/{output_filename} for your perusal")
ValueError: can't parse Gaussian output file - copied to /scratch/cwagen-gaussian/presto-IHHrJ0zo-000000001/presto-IHHrJ0zo-000000002.out for your perusal

During handling of the above exception, another exception occurred:

Traceback (most recent call last):
  File "/n/home03/cwagen/.conda/envs/openmm/lib/python3.7/multiprocessing/process.py", line 297, in _bootstrap
    self.run()
  File "/n/home03/cwagen/.conda/envs/openmm/lib/python3.7/multiprocessing/process.py", line 99, in run
    self._target(*self._args, **self._kwargs)
  File "/n/home03/cwagen/.conda/envs/openmm/lib/python3.7/site-packages/presto/calculators.py", line 362, in evaluate
    raise ValueError(f"can't parse Gaussian output file - copied to {old_working_directory}/{output_filename} for your perusal")
ValueError: can't parse Gaussian output file - copied to /net/fs2k01/srv/export/jacobsen_lab/share_root/cwagen/presto/tutorial/tutorial02/wham/presto-IHHrJ0zo-000000001.out for your perusal
